Workbook

Sheet Capacity Lite
B2: CAPACITY LITE · Tax Resolution · Revenue-Based (v2)
B3: Capacity is a REVENUE ceiling per case manager; case counts are derived. Edit the yellow (team/data) and blue (David's model definitions) cells. Model owner: David.
B5: INPUTS
B6: Full-capacity case managers (FTE) | E6: 4 | F6: people — Ramped case managers at full capacity.
B7: Case managers in training (count) | E7: 1 | F7: people — Each counts as 0.5 FTE until ramped.
B8: Current active (open) cases | E8: 350 | F8: cases — Your open book right now, all managers.
B9: New cases signed / week | E9: 25 | F9: cases/wk — Sales goal: 3 reps + James @ 6 follow-ups/day.
B10: Revenue capacity per manager ($/yr) | E10: 1000000 | F10: per mgr — David: 'full capacity' = ~$1M active book.
B11: Average case value ($) | E11: 7000 | F11: per case — David.
B12: Average case lifespan (months) | E12: 12 | F12: months — David's estimate.
B13: Comfort ceiling (% of capacity) | E13: 0.85 | F13: of cap — Utilization you don't want to exceed.
B14: DERIVED CAPACITY
B15: Effective case managers (FTE) | E15: =E6+0.5*E7 | F15: full + ½ × trainees
B16: Max active cases per manager | E16: =E10/E11 | F16: revenue ceiling ÷ case value (≈143)
B17: Total revenue capacity | E17: =E15*E10 | F17: effective FTE × ceiling/mgr
B18: Total case capacity | E18: =E15*E16 | F18: derived case ceiling
B19: Comfortable revenue capacity | E19: =E17*E13 | F19: total capacity × comfort ceiling
B20: Historical benchmark (cases/mgr, w/ admin) | E20: 130 | F20: prior reference — compare to ~143 above
B21: CURRENT STATE
B22: Current active book value | E22: =E8*E11 | F22: open cases × case value
B23: Revenue utilization | E23: =E22/E17 | F23: book value ÷ total revenue capacity
B24: Headroom to comfort ($) | E24: =E19-E22 | F24: room before the comfort ceiling
B25: Headroom to comfort (cases) | E25: =E24/E11 | F25: same headroom expressed in cases
B26: New cases / month | E26: =E9*52/12 | F26: 25/wk ≈ 108/mo
B27: Cases closing / month | E27: =E8/E12 | F27: ≈ open ÷ lifespan
B28: Net case growth / month | E28: =E26-E27 | F28: new − closing
B29: Net revenue growth / month | E29: =E28*E11 | F29: net case growth × case value
B30: Months to comfortably full | E30: =IF(E28<=0,"stable / shrinking",IF(E25<=0,"already over",E25/E28)) | F30: headroom ÷ net growth
B31: Implied annual revenue throughput | E31: =E22*(12/E12) | F31: = book value when lifespan = 12 mo
B33: =IF(E23>=E13,"ADD CAPACITY",IF(E23<=E13-0.2,"SELL MORE","MAINTAIN"))
B36: Three states: at/above the comfort ceiling → ADD CAPACITY · more than 20 pts below → SELL MORE · in between → MAINTAIN.
B37: 12-MONTH PROJECTION (assumes intake, case value & lifespan hold steady)
B38: Month | C38: Open (start) | D38: New | E38: Closed | F38: Open (end) | G38: Book value | H38: Rev. util. | I38: Status | J38: Comfort cap ($)
B39: Now | C39: — | D39: — | E39: — | F39: =E8 | G39: =F39*$E$11 | H39: =G39/$E$17 | I39: =IF(H39>=$E$13,"Add capacity",IF(H39<=$E$13-0.2,"Sell more","Maintain")) | J39: =$E$19
B40: Mo 1 | C40: =F39 | D40: =$E$26 | E40: =C40/$E$12 | F40: =MAX(0,C40+D40-E40) | G40: =F40*$E$11 | H40: =G40/$E$17 | I40: =IF(H40>=$E$13,"Add capacity",IF(H40<=$E$13-0.2,"Sell more","Maintain")) | J40: =$E$19
B41: Mo 2 | C41: =F40 | D41: =$E$26 | E41: =C41/$E$12 | F41: =MAX(0,C41+D41-E41) | G41: =F41*$E$11 | H41: =G41/$E$17 | I41: =IF(H41>=$E$13,"Add capacity",IF(H41<=$E$13-0.2,"Sell more","Maintain")) | J41: =$E$19
B42: Mo 3 | C42: =F41 | D42: =$E$26 | E42: =C42/$E$12 | F42: =MAX(0,C42+D42-E42) | G42: =F42*$E$11 | H42: =G42/$E$17 | I42: =IF(H42>=$E$13,"Add capacity",IF(H42<=$E$13-0.2,"Sell more","Maintain")) | J42: =$E$19
B43: Mo 4 | C43: =F42 | D43: =$E$26 | E43: =C43/$E$12 | F43: =MAX(0,C43+D43-E43) | G43: =F43*$E$11 | H43: =G43/$E$17 | I43: =IF(H43>=$E$13,"Add capacity",IF(H43<=$E$13-0.2,"Sell more","Maintain")) | J43: =$E$19
B44: Mo 5 | C44: =F43 | D44: =$E$26 | E44: =C44/$E$12 | F44: =MAX(0,C44+D44-E44) | G44: =F44*$E$11 | H44: =G44/$E$17 | I44: =IF(H44>=$E$13,"Add capacity",IF(H44<=$E$13-0.2,"Sell more","Maintain")) | J44: =$E$19
B45: Mo 6 | C45: =F44 | D45: =$E$26 | E45: =C45/$E$12 | F45: =MAX(0,C45+D45-E45) | G45: =F45*$E$11 | H45: =G45/$E$17 | I45: =IF(H45>=$E$13,"Add capacity",IF(H45<=$E$13-0.2,"Sell more","Maintain")) | J45: =$E$19
...

Sheet Profitability
B2: PROFITABILITY · New Compensation Model
B3: Annual run-rate. Compares the OLD comp model vs the NEW (growth-incentive) model at the intake each one actually drives. Edit yellow (data) and blue (comp terms) cells.
B5: INPUTS
B6: Average case value ($) | E6: ='Capacity Lite'!E11 | G6: linked from Capacity Lite
B7: Average case lifespan (months) | E7: ='Capacity Lite'!E12 | G7: linked from Capacity Lite
B8: Max active cases per manager | E8: ='Capacity Lite'!E16 | G8: linked (≈143)
B9: Collection rate (% of signed value) | E9: 0.85 | G9: share of signed fees actually collected
B10: Intake UNDER OLD comp (cases/week) | E10: 12 | G10: what James/reps produce on salary
B11: Intake UNDER NEW comp (cases/week) | E11: 25 | G11: the incentivized target: 3 reps + James
B12: James base — OLD ($/yr) | E12: 90000 | G12: salary-heavy
B13: James base — NEW ($/yr) | E13: 60000 | G13: reduced base, upside from commission
B14: James commission — NEW (% of signed value) | E14: 0.01 | G14: growth commission
B15: Number of sales reps | E15: 3
B16: Rep base — OLD ($/yr each) | E16: 60000
B17: Rep base — NEW ($/yr each) | E17: 45000
B18: Reps commission — NEW (% pooled) | E18: 0.02 | G18: across all reps, of signed value
B19: Case manager loaded comp ($/yr) | E19: 75000 | G19: delivery cost per manager FTE
B20: MG&A overhead — fixed ($/yr) | E20: 300000 | G20: rent, software, admin
B21: MG&A overhead — variable (% of collected rev) | E21: 0.3 | G21: marketing / lead-gen scales with revenue
B23: ANNUAL RUN-RATE P&L
B24: Line | E24: OLD comp | G24: NEW comp | H24: Notes
B25: Intake (cases/week) | E25: =E10 | G25: =E11 | H25: behavioral: new comp lifts volume
B26: Annual signed case value | E26: =(E10*52*E6) | G26: =(E11*52*E6) | H26: cases/wk × 52 × case value
B27: Collected revenue | E27: =(E10*52*E6)*E9 | G27: =(E11*52*E6)*E9 | H27: signed × collection rate
B28: Case managers required (FTE) | E28: =(E10*52*(E7/12))/E8 | G28: =(E11*52*(E7/12))/E8 | H28: active cases ÷ max per mgr
B29: Case manager cost | E29: =-((E10*52*(E7/12))/E8*E19) | G29: =-((E11*52*(E7/12))/E8*E19) | H29: required FTE × loaded comp
B30: James pay | E30: =-E12 | G30: =-(E13+E14*(E11*52*E6)) | H30: OLD base | NEW base + commission
B31: Sales reps pay | E31: =-(E15*E16) | G31: =-(E15*E17+E18*(E11*52*E6)) | H31: OLD base | NEW base + pooled commission
B32: MG&A overhead | E32: =-(E20+E21*((E10*52*E6)*E9)) | G32: =-(E20+E21*((E11*52*E6)*E9)) | H32: fixed + variable % of collected rev
B33: NET PROFIT | E33: =(((E10*52*E6)*E9)-((E10*52*(E7/12))/E8*E19)-E12-(E15*E16)-(E20+E21*((E10*52*E6)*E9))) | G33: =(((E11*52*E6)*E9)-((E11*52*(E7/12))/E8*E19)-(E13+E14*(E11*52*E6))-(E15*E17+E18*(E11*52*E6))-(E20+E21*((E11*52*E6)*E9))) | H33: collected rev − all costs
B34: Net margin | E34: =(((E10*52*E6)*E9)-((E10*52*(E7/12))/E8*E19)-E12-(E15*E16)-(E20+E21*((E10*52*E6)*E9)))/((E10*52*E6)*E9) | G34: =(((E11*52*E6)*E9)-((E11*52*(E7/12))/E8*E19)-(E13+E14*(E11*52*E6))-(E15*E17+E18*(E11*52*E6))-(E20+E21*((E11*52*E6)*E9)))/((E11*52*E6)*E9)
B36: PROFITABILITY IMPACT OF THE NEW COMP MODEL
B37: Δ Collected revenue (new − old) | E37: =((E11*52*E6)*E9)-((E10*52*E6)*E9) | G37: the growth the incentive unlocks
B38: Δ Selling comp cost (new − old) | E38: =-(((E13+E14*(E11*52*E6))+(E15*E17+E18*(E11*52*E6)))-(E12+(E15*E16))) | G38: extra commission the firm pays out
B39: Δ NET PROFIT (new − old) | E39: =(((E11*52*E6)*E9)-((E11*52*(E7/12))/E8*E19)-(E13+E14*(E11*52*E6))-(E15*E17+E18*(E11*52*E6))-(E20+E21*((E11*52*E6)*E9)))-(((E10*52*E6)*E9)-((E10*52*(E7/12))/E8*E19)-E12-(E15*E16)-(E20+E21*((E10*52*E6)*E9))) | G39: bottom-line effect of switching
B41: =IF(E39>=0,"NEW COMP MODEL IS ACCRETIVE — pays for itself through growth","NEW COMP COSTS MORE — justify via the added revenue & retention")
B44: NOTES & ASSUMPTIONS
B45: • Commission basis = NEW SIGNED case value (rewards growth). James responds to visuals — see the 'James — New Comp' tab.
B46: • The comparison is intentionally apples-to-oranges on VOLUME: the whole point of the new model is that it lifts intake (old ≈12/wk → new ≈25/wk). Set both intake cells to the same number to isolate the pure cost swap instead.
B47: • Run-rate view: at steady state, annual signed value ≈ annual recognized revenue. During rapid ramp, commission (paid on signings) leads revenue — watch cash timing separately.
...

Sheet James — New Comp
B2: WHY THE NEW MODEL PAYS JAMES MORE
B3: Old model = flat salary no matter how much the firm grows. New model = lower base + commission on new signed cases, so his pay climbs with the growth he drives.
B5: James base — OLD | C5: ='Profitability'!E12 | E5: Target intake (cases/wk) | F5: ='Profitability'!E11
B6: James base — NEW | C6: ='Profitability'!E13
B7: Commission % (signed value) | C7: ='Profitability'!E14
B8: Case value | C8: ='Profitability'!E6
B11: Cases / week | C11: Signed value / yr | D11: James OLD ($) | E11: James NEW ($) | F11: Δ to James
B12: 0 | C12: =B12*52*$C$8 | D12: =$C$5 | E12: =$C$6+$C$7*C12 | F12: =E12-D12
B13: 2.5 | C13: =B13*52*$C$8 | D13: =$C$5 | E13: =$C$6+$C$7*C13 | F13: =E13-D13
B14: 5 | C14: =B14*52*$C$8 | D14: =$C$5 | E14: =$C$6+$C$7*C14 | F14: =E14-D14
B15: 7.5 | C15: =B15*52*$C$8 | D15: =$C$5 | E15: =$C$6+$C$7*C15 | F15: =E15-D15
B16: 10 | C16: =B16*52*$C$8 | D16: =$C$5 | E16: =$C$6+$C$7*C16 | F16: =E16-D16
B17: 12.5 | C17: =B17*52*$C$8 | D17: =$C$5 | E17: =$C$6+$C$7*C17 | F17: =E17-D17
B18: 15 | C18: =B18*52*$C$8 | D18: =$C$5 | E18: =$C$6+$C$7*C18 | F18: =E18-D18
B19: 17.5 | C19: =B19*52*$C$8 | D19: =$C$5 | E19: =$C$6+$C$7*C19 | F19: =E19-D19
B20: 20 | C20: =B20*52*$C$8 | D20: =$C$5 | E20: =$C$6+$C$7*C20 | F20: =E20-D20
B21: 22.5 | C21: =B21*52*$C$8 | D21: =$C$5 | E21: =$C$6+$C$7*C21 | F21: =E21-D21
B22: 25 | C22: =B22*52*$C$8 | D22: =$C$5 | E22: =$C$6+$C$7*C22 | F22: =E22-D22
B23: 27.5 | C23: =B23*52*$C$8 | D23: =$C$5 | E23: =$C$6+$C$7*C23 | F23: =E23-D23
... B28: 40 | C28: =B28*52*$C$8 | D28: =$C$5 | E28: =$C$6+$C$7*C28 | F28: =E28-D28
B30: =CONCATENATE("At the ",TEXT($F$5,"0")," cases/week goal: OLD ",TEXT(D22,"$#,##0")," → NEW ",TEXT(E22,"$#,##0")," (",TEXT(F22,"+$#,##0"),"/yr for James)")
B31: The lines cross near ~8 cases/week — beyond that, James earns more under the new model, and it keeps climbing.
